Workbook

Sheet Personalized Academic Calendar
A1: STREAM | C1: 4 | G1: Divider | H1: # Courses from List | J1: Count | K1: Status
A2: Term | B2: When | F2: Elective List | H2: Technical Electives | I2: 1 | J2: =COUNTIF(F:F,"List 1") -> 1 | K2: =IF(J3+J4=4,"Good", IF(J3+J4<4,"Not Enough TEs", "Too Many TEs")) -> Good
A3: 1A | B3: =IF($C$1=4, _xlfn.XLOOKUP(A3,'Study Work Sequence Chart '!$B$2:$B$15,'Study Work Sequence Chart '!$C$2:$C$15),_xlfn.XLOOKUP(A3,'Study Work Sequence Chart '!$B$16:$B$29,'Study Work Sequence Chart '!$C$16:$C$29)) -> Fall 26 | C3: 1A | D3: Chemical Engineering Concepts 1 | E3: 0.5 | I3: 2 | J3: =COUNTIF(F:F,"List 2") -> 2
C4: CHE102 | D4: Chemistry for Engineers | E4: 0.5 | H4: Complimentary Electives | I4: A | J4: =COUNTIF(F:F,"List A") -> 2 | K4: =IF(J4=0, "Not Enough From List A", IF(J5>2, "Too Many From List A", "Good")) -> Good
C5: CHE120 | D5: Computer Literacy and Programming for Chemical Engineers | E5: 0.5 | I5: B | J5: =COUNTIF(F:F,"List B") -> 0 | K5: =IF(J5<>0, "Too Many From List B", "Good") -> Good
C6: CHE180 | D6: Chemical Engineering Design Studio 1 | E6: 0.5 | I6: C | J6: =COUNTIF(F:F,"List C") -> 1 | K6: =IF(J7=0, "Not Enough From List C", IF(J7>2, "Too Many From List C", "Good")) -> Good
C7: MATH115 | D7: Linear Algebra for Engineering | E7: 0.5 | I7: D | J7: =COUNTIF(F:F,"List D") -> 1 | K7: =IF(J8>1, "Too Many From List D", "Good") -> Good
C8: MATH116 | D8: Calculus 1 for Engineering | E8: 0.5
A9: 1B | B9: =IF($C$1=4,_xlfn.XLOOKUP(A9,'Study Work Sequence Chart '!$B$2:$B$15,'Study Work Sequence Chart '!$C$2:$C$15),_xlfn.XLOOKUP(A9,'Study Work Sequence Chart '!$B$16:$B$29,'Study Work Sequence Chart '!$C$16:$C$29)) -> Summer 27 | C9: CHE101 | D9: Chemical Engineering Concepts 2 | E9: 0.5
C10: CHE161 | D10: Engineering Biology | E10: 0.5
C11: CHE181 | D11: Chemical Engineering Design Studio 2 | E11: 0.5
C12: CHE191 | D12: Chemical Engineering Concepts Laboratory | E12: 0.25
C13: MATH118 | D13: Calculus 2 for Engineering | E13: 0.5
C14: PHYS115 | D14: Mechanics | E14: 0.5
C15: COMMST191 | D15: =VLOOKUP(C15,'Elective Lists'!$B$2:$D$352, 2,FALSE) -> Communication in the Engineering Profession (AE, CHE, CIVE, ENVE, GEOE) | E15: =VLOOKUP(C15,'Elective Lists'!$B$2:$D$352, 3,FALSE) -> 0.5
A16: 2A | B16: =IF($C$1=4,_xlfn.XLOOKUP(A16,'Study Work Sequence Chart '!$B$2:$B$15,'Study Work Sequence Chart '!$C$2:$C$15),_xlfn.XLOOKUP(A16,'Study Work Sequence Chart '!$B$16:$B$29,'Study Work Sequence Chart '!$C$16:$C$29)) -> Winter 28 | C16: CHE200 | D16: Equilibrium Stage Operations | E16: 0.5
C17: CHE220 | D17: Probability and Statistics | E17: 0.5
C18: CHE230 | D18: Physical Chemistry 1 | E18: 0.5
C19: CHE290 | D19: Chemical Engineering Laboratory 1 | E19: 0.25
C20: CHEM262 | D20: Organic Chemistry for Engineering | E20: 0.5
C21: CHEM262L | D21: Organic Chemistry Laboratory for Engineering Students | E21: 0.25
C22: MATH217 | D22: Calculus 3 for Chemical Engineering | E22: 0.5
A23: 2B | B23: =IF($C$1=4,_xlfn.XLOOKUP(A23,'Study Work Sequence Chart '!$B$2:$B$15,'Study Work Sequence Chart '!$C$2:$C$15),_xlfn.XLOOKUP(A23,'Study Work Sequence Chart '!$B$16:$B$29,'Study Work Sequence Chart '!$C$16:$C$29)) -> Fall 28 | C23: CHE211 | D23: Fluid Mechanics | E23: 0.5
C24: CHE225 | D24: Design of Experiments for Process Improvement | E24: 0.5
C25: CHE241 | D25: Materials Science and Engineering | E25: 0.5
C26: CHE291 | D26: Chemical Engineering Laboratory 2 | E26: 0.25
C27: MATH218 | D27: Differential Equations for Engineers | E27: 0.5
C28: GEOG326 | D28: =VLOOKUP(C28,'Elective Lists'!$B$2:$D$352, 2,FALSE) -> Environment and Development in a Global Perspective | E28: =VLOOKUP(C28,'Elective Lists'!$B$2:$D$352, 3,FALSE) -> 0.5 | F28: =_xlfn.XLOOKUP(C28,'Elective Lists'!$B:$B,'Elective Lists'!$A:$A) -> List A
A29: 3A | B29: =IF($C$1=4,_xlfn.XLOOKUP(A29,'Study Work Sequence Chart '!$B$2:$B$15,'Study Work Sequence Chart '!$C$2:$C$15),_xlfn.XLOOKUP(A29,'Study Work Sequence Chart '!$B$16:$B$29,'Study Work Sequence Chart '!$C$16:$C$29)) -> Summer 29 | C29: CHE312 | D29: Mathematics of Heat and Mass Transfer | E29: 0.5
C30: CHE314 | D30: Chemical Reaction Engineering | E30: 0.5
C31: CHE322 | D31: Numerical Methods for Process Analysis and Design | E31: 0.5
C32: CHE330 | D32: Chemical Engineering Thermodynamics | E32: 0.5
C33: CHE380 | D33: Sustainability in Chemical Engineering | E33: 0.5
C34: CHE390 | D34: Chemical Engineering Laboratory 3 | E34: 0.5
A35: 3B | B35: =IF($C$1=4,_xlfn.XLOOKUP(A35,'Study Work Sequence Chart '!$B$2:$B$15,'Study Work Sequence Chart '!$C$2:$C$15),_xlfn.XLOOKUP(A35,'Study Work Sequence Chart '!$B$16:$B$29,'Study Work Sequence Chart '!$C$16:$C$29)) -> Fall 29 | C35: CHE313 | D35: Applications of Heat and Mass Transfer | E35: 0.5
C36: CHE331 | D36: Electrochemical Engineering | E36: 0.5
C37: CHE341 | D37: Introduction to Process Control | E37: 0.5
C38: CHE361 | D38: Bioprocess Engineering | E38: 0.5
C39: CHE383 | D39: Chemical Engineering Design Workshop | E39: 0.25
C40: MSE551 | D40: =VLOOKUP(C40,'Elective Lists'!$B$2:$D$352, 2,FALSE) -> Quality Management and Control | E40: =VLOOKUP(C40,'Elective Lists'!$B$2:$D$352, 3,FALSE) -> 0.5 | F40: =_xlfn.XLOOKUP(C40,'Elective Lists'!$B:$B,'Elective Lists'!$A:$A) -> List 2
...

Sheet Elective Lists
A1: List | B1: Course ID | C1: Course Name | D1: Credit
A2: 1B | B2: COMMST191 | C2: Communication in the Engineering Profession (AE, CHE, CIVE, ENVE, GEOE) | D2: 0.5
B3: ENGL191 | C3: Communication in the Engineering Profession (AE, CHE, CIVE, ENVE, GEOE) | D3: 0.5
A4: 4A | B4: CHE482 | C4: Group Design Project | D4: 0.5
B5: GENE403 | C5: Interdisciplinary Design Project 1 | D5: 0.5
A6: 4B | B6: CHE483 | C6: Group Design Project and Symposium | D6: 0.5
B7: GENE404 | C7: Interdisciplinary Design Project 2 | D7: 0.5
A8: Ethics | B8: ARBUS202 | C8: Professional and Business Ethics | D8: 0.5
B9: PD22 | C9: Professionalism and Ethics in Engineering Practice | D9: 0.5
B10: PHIL215 | C10: Professional and Business Ethics | D10: 0.5
B11: PHIL219J | C11: Practical Ethics | D11: 0.5
B12: PHIL315 | C12: Ethics and the Engineering Profession | D12: 0.5
A13: List 1 | B13: CHE500 | C13: Special Topics in Chemical Engineering | D13: 0.5
A14: List 1 | B14: CHE514 | C14: Fundamentals of Petroleum Production | D14: 0.5
A15: List 1 | B15: CHE516 | C15: Energy Systems Engineering | D15: 0.5
A16: List 1 | B16: CHE520 | C16: Process Modelling and Simulation | D16: 0.5
A17: List 1 | B17: CHE521 | C17: Process Optimization | D17: 0.5
A18: List 1 | B18: CHE522 | C18: Advanced Process Dynamics and Control | D18: 0.5
A19: List 1 | B19: CHE523 | C19: Introduction to Machine Learning and Data Science | D19: 0.5
A20: List 1 | B20: CHE524 | C20: Process Control Laboratory | D20: 0.5
A21: List 1 | B21: CHE541 | C21: Introduction to Polymer Science and Properties | D21: 0.5
A22: List 1 | B22: CHE543 | C22: Polymer Production: Polymer Reaction Engineering | D22: 0.5
A23: List 1 | B23: CHE560 | C23: Nanomedicine and Nanobiotechnology | D23: 0.5
A24: List 1 | B24: CHE561 | C24: Biomaterials and Tissue Engineering | D24: 0.5
... A352: List D | B352: THPERF440 | C352: Performative Inquiry and Practice | D352: 0.5

Sheet Study Work Sequence Chart 
A1: Stream | B1: Term | C1: Time
A2: 4 | B2: 1A | C2: Fall 26
B3: WT1 | C3: Winter 27
B4: 1B | C4: Summer 27
B5: WT2 | C5: Fall 27
B6: 2A | C6: Winter 28
B7: WT3 | C7: Summer 28
B8: 2B | C8: Fall 28
B9: WT4 | C9: Winter 29
B10: 3A | C10: Summer 29
B11: 3B | C11: Fall 29
B12: WT5 | C12: Winter 30
B13: WT6 | C13: Summer 30
B14: 4A | C14: Fall 30
B15: 4B | C15: Winter 31
A16: 8 | B16: 1A | C16: Fall 26
B17: 1B | C17: Winter 27
B18: WT1 | C18: Summer 27
B19: 2A | C19: Fall 27
B20: WT2 | C20: Winter 28
B21: 2B | C21: Summer 28
B22: WT3 | C22: Fall 28
B23: 3A | C23: Winter 29
B24: WT4 | C24: Summer 29
B25: WT5 | C25: Fall 29
B26: 3B | C26: Winter 30
B27: WT6 | C27: Summer 30
B28: 4A | C28: Fall 30
B29: 4B | C29: Winter 31
